# 代数效应

- 整个 react 就是代数效应
- <suspense>中包裹的组件，里面写的是同步的异步代码，该组件执行了两次、
  - 第一次是抛出了一个 promise 错误，执行真实请求，set cache，状态设置为 fallback
  - 第二次是读取 cache，重新渲染，取消 fallback 状态

# 异步函数具有传染性

```js
async function getUser() {
  return await fetch('./1.json')
}

async function m1() {
  const user = await getUser()

  return user
}

async function m2() {
  const user = await m1()
  return user
}

async function m3() {
  const user = await m2()
  return user
}

async function main() {
  const user = await m3()
  console.log(user)
}
```

# 消除异步

- 根源：getUser 是异步，把他变成同步
- **方案：让 fetch 的第一次立刻失败，抛出一个 promise 错误，然后捕获到这个错误，去执行第二次的 fetch**
- fetch =》有没有缓存？=》有，直接返回缓存；没有，进行 request，并 set cache

# 提供执行环境的思想

- 把 main 放到 run 这个环境中去执行
- 在 run 中去改变环境
  - 在 run 中改变 fetch，执行完 func 后再把 fetch 改回来

```js
async function main() {
  const user = await m3()
  console.log(user)
}

function run(func) {
  // 执行 func 前，改变环境中的 fetch
  const oldFetch = window.fetch

  let cache = {
    status: 'pending',
    value: null
  }

  window.fetch = function (...args) {
    if (cache.status === 'fulfilled') {
      return cache.value
    } else if (cache.status === 'rejected') {
      throw cache.value
    }

    // 1. 进行真实请求
    // then 返回的还是一个 promise
    const prom = oldFetch(...args).then(
      (res) => {
        cache.status = 'fulfilled'
        cache.value = res
      },
      (err) => {
        cache.status = 'rejected'
        cache.value = err
      }
    )

    // 2. 第一次 fetch ，直接抛出错误，抛出一个 promise，给予第二次执行的时机
    throw prom
  }

  // 执行入口文件
  try {
    // 使用 try catch 包裹，catch 第一次 fetch 主动抛出的错误，进而触发第二次 fetch，直接获取 cache
    func()
  } catch (e) {
    if (Object.prototype.toString.call(e) === '[object Promise]') {
      // 这里是前面 fetch 第一次返回的 promise，让他 then，再次去执行 func
      // finally 中把 fetch 恢复
      e.then(func, func).finally(() => {
        window.fetch = oldFetch
      })
    }
  }
}

run(main)
```
